---
layout: post
title: "파이썬 예외처리"
categories: 공부
date: 2023-01-09 23:59:00+0900
tags: [파이썬, 예외처리, 공부, 정리]
---

# 예외처리

우리는 프로그램을 만들다보면 많은 오류들과 만나게 된다. 여러 이유로 인해 오류가 발생 하지만 
이런 오류 메세지들은 프로그램이 잘못 동작하는 것을 막기 위한 배려 같은 것이다.
이런 오류들을 처리하는 방법을 알아 볼 것이다.


## 오류가 발생하는 때
먼저 오류는 어떨때 발생을 하는지 알아 보도록 하자.  
오타로 발생하는 오류는 빼고 실제 자주 발생하는 오류들로 한번 알아보자.

존재 하지 않는 파일을 사용할때엔 

```
>>> f = open("파일없음", 'r')
Traceback (most recent call last):
  File "<stdin>", line 1, in <module>
FileNotFoundError: [Errno 2] No such file or directory: '파일없음'
```

에러가 뜬다 에러 이름을 보면 FileNotFoundError 라고 쓰여져 있다.  
그리고 0으로 다른 숫자를 나누는 오류는 자주 발생 한다.

```
>>> 6 / 0
Traceback (most recent call last):
  File "<stdin>", line 1, in <module>
ZeroDivisionError: division by zero
```
이것도 이름을 보면 ZeroDivisionError 라고 뜬다.

이번에 보여줄 오류는 아주 번번히 나오는 오류이다.

```
>>> a = [1,2,3]
>>> a[4]
Traceback (most recent call last):
  File "<stdin>", line 1, in <module>
IndexError: list index out of range
```

이런식으로 리스트에 없는 숫자를 불러올때 얻을 수 없는 값이라는 걸 알려주는 IndexError이다.

이러한 오류들이 발생하면 프로그램을 중단하고 오류 메세지를 보낸다.

## 오류 예외 처리 기법

### try, except문

```
try:
    ...
except [발생오류 [as 오류변수]]:
    ...
```

이런식으로 사용 되는 오류 처리 방법 이다.

try 블록을 수행중에 오류가 발생하면 프로그램을 중단하고 오류 메세지를 보여주는것이 아닌  
except블록이 수행이 된다.

3가지로 사용방법이 있는데 한개씩 알아보자.


#### try,except만 사용

```
try:
    ...
except:
    ...
```

이런 방식은 어떤 오류가 발생하던 except블록을 수행한다.


#### 발생 오류만 포함한 except문

```
try:
    ...
except 발생오류:
    ...
```

이런 경우 오류가 발생하면 미리 정한 오류인 경우에만 except 블록을 수행한다.


#### 발생오류와 오류변수까지 포함한 except문

```
try:
    ...
except 발생오류 as 오류변수:
    ...
```

오류의 내용까지 알고 싶을때 사용하는 방법으로 한번 예를 보고 배워보자

``` 
try:
    5 / 0
except ZeroDivisionError as e:
    print(e)
```

이렇게 0으로 나눌려고 하면 발생하는 오류를 지정하여 오류변수 e에 담기는 오류 메세지를 출력  
할 수 있다. 오류 메세지는 division by zero 라고 나온다.

## try .. finally

try 문에서는 finally절을 사용할 수 있다. 보통 finally 절은 사용한 리소스를 닫아야 할 때 만이  
쓰인다.


```
try:
    f = open('foo.txt', 'w')
    # 무언가를 수행한다.
    ...

finally:
    f.close()  # 중간에 오류가 발생하더라도 무조건 실행된다.
```

이렇게 파일을 쓰기모드로 열고 try문을 수행후 예외 발생과 상관없이 finally절에서 열린  
파일을 닫을 수 있다.

## 여러개 오류 처리하기

만일 try문에서 여러 개의 오류가 발생하면 어떻게 처리하면 될까?

```
try:
    ...
except 발생오류1:
   ... 
except 발생오류2:
   ...
```

이러한 방식으로 여러개의 오류도 처리가 가능하다.

그럼 한번 만들어서 사용해 보자

```
try:
    a = [1,2]
    print(a[3])
    5/0
except ZeroDivisionError:
    print("0으로 나눌 수 없습니다.")
except IndexError:
    print("인덱싱 할 수 없습니다.")
```

이러한 방식으로 두가지 오류를 만들어서 처리 되게 했다. 
어떻게 생각 하면 두가지 모두 출력이 될꺼 같지만 먼저 발생된 오류 만 출력인 된다.
except 순서에 상관 없이 try문에서 제일 먼저 발생된 오류만 출력이 된다.

다른 아까 봤던 오류변수로도 한번 만들어 보자

```
try:
    a = [1,2]
    print(a[3])
    5/0
except ZeroDivisionError as e:
    print(e)
except IndexError as e:
    print(e)
```

이렇게 만들어서 확인해도 제일 먼저 발생된 오류인 list index out of range 이란   
오류 메세지가 출력 된다.

또 하나의 처리 방법도 있다.

```
try:
    a = [1,2]
    print(a[3])
    5/0
except (ZeroDivisionError, IndexError) as e:
    print(e)
```

이렇게 괄호로 묶어서 사용하면 두가지 이상의 오류를 처리 할 수 있다.

## try ... else

if문에서 봤던 else절을 여기서도 사용이 가능하다.

```
try:
    ...
except [발생오류 [as 오류변수]]:
    ...
else:  # 오류가 없을 경우에만 수행된다.
    ...
```

이런식으로 사용이 되고 오류가 발생하면 except절이 수행되고 오류가 없다면 else절이 수행 된다.

간단하게 예시를 만들어보자

```
try:
    password=int(input('비밀번호를 4자리 입력하세요:'))
except:
    print('입력이 정확하지 않습니다.')
else:
    if password == 3930:
        print('환영합니다.')
    else:
        print("비밀번호를 잘못 입력 하셨습니다.")
```

이렇게 비밀번호를 입력 받는 예제를 만들었다 만약 숫자가 아닌 다른 이상한 것을 입력하면   
'입력이 정확하지 않습니다.' 를 출력하고 비밀번호가 맞다면 '환영합니다.'를 만약 아니라면  
"비밀번호를 잘못 입력 하셨습니다." 를 출력하게 했다.


## 오류 회피하기

만약 특정 오류를 그냥 패스 시키고 싶다면?

```
try:
    f = open("파일없음", 'r')
except FileNotFoundError:
    pass
```

이런식으로 pass를 이용해서 회피할 수 있다.


## 오류 발생시키기

오류를 일부러 발생하는 경우가 생기기도 한다.  
raise 명령어를 사용해 오류를 강제로 발생시킬 수 있다.

```
class Mammal:
    def run(self):
        raise NotImplementedError
```

이러한 방식으로 클래스로 run이라는 함수를 구현하도록 만들고 싶다.  
 치타란 클래스를 상속 받는 자식 클래스는 반드시 run 함수를 넣어야 한다.  
만약 넣지 않는다면 오류가 발생 되게 만들었다.  
한번 run을 넣지 않은 함수를 호출해보자.  

```
class Cheetah(Mammal):
    pass

cheetah = Cheetah()
cheetah.run()
```

```
Traceback (most recent call last):
  File "...", line 33, in <module>
    cheetah.run()
  File "...", line 26, in run
    raise NotImplementedError
NotImplementedError
```
Mammal 클래스를 상속받은 Cheetah 클래스에서 run 매서드를 오버라이딩하여 구현하지 않고
run매서드를 수행하니 Mammal의 run매서드가 수행되 NotImplementedError가 발생 했다.

이런 오류를 발생하지 않게 하려면 Cheetah 클래스에 run 함수를 만들어야 한다.

```
class Cheetah(Mammal):
    def run(self):
        print("hunting")

eagle = Eagle()
eagle.fly()
```

이렇게 만들고 실행하면 오류없이 hunting을 출력한다.


## 예외 만들기

프로그햄 수행 하는중 특수한 경우 예외 처리를 하기 위해서 만들어 사용한다.  
예외는 파이썬 내장 클래스인 Exception 클래스를 상속하여 만들 수 있다.

```
class MyError(Exception):
    pass

def say_nick(nick):
    if nick == '멍청이':
        raise MyError()
    print(nick)

say_nick("천재")
say_nick("멍청이")

```

이렇게 별명을 출력 하는 함수를 만들어 출력해 보면 
천재를 호출하고 MyError가 발생한다.

```
천재
Traceback (most recent call last):
  File "...", line 11, in <module>
    say_nick("멍청이")
  File "...", line 7, in say_nick
    raise MyError()
__main__.MyError
```

예외처리 기법으로 발생한 애러를 처리해보자.

```
try:
    say_nick("천재")
    say_nick("멍청이")
except MyError:
    print("허용되지 않는 별명입니다.")
```

이렇게 만들어 출력을 해보면

```
천재
허용되지 않는 별명입니다.
```

이렇게 출력된다.

만약 오류 메세지를 보고 싶다면 

```
try:
    say_nick("천재")
    say_nick("멍청이")
except MyError as e:
    print(e)
```

이렇게 만들면 출력이 될꺼라 생각을 할것이다. 하지만 천재만 출력되고 아무것도 출력이 되지 않는다.
만약 메세지를 보이게 할려면 오류 클래스에 __str__ 매서드를 구현해야 오류 메세지를 뜨게 할 수 있다.  

```
class MyError(Exception):
    def __str__(self):
        return "허용되지 않는 별명입니다."

def say_nick(nick):
    if nick == '멍청이':
        raise MyError()
    print(nick)

try:
    say_nick("천재")
    say_nick("멍청이")
except MyError as e:
    print(e)
```

이런식으로 에러 클레스에 만들어주면 "허용되지 않는 별명입니다." 라는 메세지가 출력 된다.





이 포스팅은 점프투 파이썬을 보고 정리한 자료입니다.
